Traceback (most recent call last):
  File "/opt/miniconda3/envs/tf2/lib/python3.9/site-packages/jupyter_cache/executors/utils.py", line 51, in single_nb_execution
    executenb(
  File "/opt/miniconda3/envs/tf2/lib/python3.9/site-packages/nbclient/client.py", line 1204, in execute
    return NotebookClient(nb=nb, resources=resources, km=km, **kwargs).execute()
  File "/opt/miniconda3/envs/tf2/lib/python3.9/site-packages/nbclient/util.py", line 84, in wrapped
    return just_run(coro(*args, **kwargs))
  File "/opt/miniconda3/envs/tf2/lib/python3.9/site-packages/nbclient/util.py", line 62, in just_run
    return loop.run_until_complete(coro)
  File "/opt/miniconda3/envs/tf2/lib/python3.9/asyncio/base_events.py", line 647, in run_until_complete
    return future.result()
  File "/opt/miniconda3/envs/tf2/lib/python3.9/site-packages/nbclient/client.py", line 663, in async_execute
    await self.async_execute_cell(
  File "/opt/miniconda3/envs/tf2/lib/python3.9/site-packages/nbclient/client.py", line 965, in async_execute_cell
    await self._check_raise_for_error(cell, cell_index, exec_reply)
  File "/opt/miniconda3/envs/tf2/lib/python3.9/site-packages/nbclient/client.py", line 862, in _check_raise_for_error
    raise CellExecutionError.from_cell_and_msg(cell, exec_reply_content)
nbclient.exceptions.CellExecutionError: An error occurred while executing the following cell:
------------------
print(pd.DataFrame(df['PERSON.NUMBER'].value_counts().describe()).T)

f, (ax_box, ax_hist) = plt.subplots(2, sharex=True, 
                                    gridspec_kw={"height_ratios": (.15, .85)})

sns.boxplot(x=df['PERSON.NUMBER'].value_counts(), ax=ax_box)
sns.histplot(x=df['PERSON.NUMBER'].value_counts(), 
             bins=12, ax=ax_hist)

ax_box.set(yticks=[])
sns.despine(ax=ax_hist)
sns.despine(ax=ax_box, left=True)
------------------

[0;31m---------------------------------------------------------------------------[0m
[0;31mNameError[0m                                 Traceback (most recent call last)
Cell [0;32mIn [12], line 6[0m
[1;32m      1[0m [38;5;28mprint[39m(pd[38;5;241m.[39mDataFrame(df[[38;5;124m'[39m[38;5;124mPERSON.NUMBER[39m[38;5;124m'[39m][38;5;241m.[39mvalue_counts()[38;5;241m.[39mdescribe())[38;5;241m.[39mT)
[1;32m      3[0m f, (ax_box, ax_hist) [38;5;241m=[39m plt[38;5;241m.[39msubplots([38;5;241m2[39m, sharex[38;5;241m=[39m[38;5;28;01mTrue[39;00m, 
[1;32m      4[0m                                     gridspec_kw[38;5;241m=[39m{[38;5;124m"[39m[38;5;124mheight_ratios[39m[38;5;124m"[39m: ([38;5;241m.15[39m, [38;5;241m.85[39m)})
[0;32m----> 6[0m [43msns[49m[38;5;241m.[39mboxplot(x[38;5;241m=[39mdf[[38;5;124m'[39m[38;5;124mPERSON.NUMBER[39m[38;5;124m'[39m][38;5;241m.[39mvalue_counts(), ax[38;5;241m=[39max_box)
[1;32m      7[0m sns[38;5;241m.[39mhistplot(x[38;5;241m=[39mdf[[38;5;124m'[39m[38;5;124mPERSON.NUMBER[39m[38;5;124m'[39m][38;5;241m.[39mvalue_counts(), 
[1;32m      8[0m              bins[38;5;241m=[39m[38;5;241m12[39m, ax[38;5;241m=[39max_hist)
[1;32m     10[0m ax_box[38;5;241m.[39mset(yticks[38;5;241m=[39m[])

[0;31mNameError[0m: name 'sns' is not defined
NameError: name 'sns' is not defined

