Traceback (most recent call last):
  File "/opt/miniconda3/envs/tf2/lib/python3.9/site-packages/nbclient/client.py", line 730, in _async_poll_for_reply
    msg = await ensure_async(self.kc.shell_channel.get_msg(timeout=new_timeout))
  File "/opt/miniconda3/envs/tf2/lib/python3.9/site-packages/nbclient/util.py", line 96, in ensure_async
    result = await obj
  File "/opt/miniconda3/envs/tf2/lib/python3.9/site-packages/jupyter_client/channels.py", line 230, in get_msg
    raise Empty
_queue.Empty

During handling of the above exception, another exception occurred:

Traceback (most recent call last):
  File "/opt/miniconda3/envs/tf2/lib/python3.9/site-packages/jupyter_cache/executors/utils.py", line 51, in single_nb_execution
    executenb(
  File "/opt/miniconda3/envs/tf2/lib/python3.9/site-packages/nbclient/client.py", line 1204, in execute
    return NotebookClient(nb=nb, resources=resources, km=km, **kwargs).execute()
  File "/opt/miniconda3/envs/tf2/lib/python3.9/site-packages/nbclient/util.py", line 84, in wrapped
    return just_run(coro(*args, **kwargs))
  File "/opt/miniconda3/envs/tf2/lib/python3.9/site-packages/nbclient/util.py", line 62, in just_run
    return loop.run_until_complete(coro)
  File "/opt/miniconda3/envs/tf2/lib/python3.9/asyncio/base_events.py", line 647, in run_until_complete
    return future.result()
  File "/opt/miniconda3/envs/tf2/lib/python3.9/site-packages/nbclient/client.py", line 663, in async_execute
    await self.async_execute_cell(
  File "/opt/miniconda3/envs/tf2/lib/python3.9/site-packages/nbclient/client.py", line 949, in async_execute_cell
    exec_reply = await self.task_poll_for_reply
  File "/opt/miniconda3/envs/tf2/lib/python3.9/site-packages/nbclient/client.py", line 754, in _async_poll_for_reply
    await self._async_handle_timeout(timeout, cell)
  File "/opt/miniconda3/envs/tf2/lib/python3.9/site-packages/nbclient/client.py", line 801, in _async_handle_timeout
    raise CellTimeoutError.error_from_timeout_and_cell(
nbclient.exceptions.CellTimeoutError: A cell timed out while it was being executed, after 30 seconds.
The message was: Cell execution timed out.
Here is a preview of the cell contents:
-------------------
["with open('data/artist_event_records.json') as json_file: event_artist_records=json.load(json_file)", '', 'artists_with_exhibitions=pd.DataFrame()', 'for event_with_artists in event_artist_records:', "    for artist in event_with_artists['artist_bio']:"]
...
['.reset_index()\\', ".sort_values('index')", '', "events_females_tab = events_females_tab[events_females_tab['index'] > 1910]", "events_females_tab['gender'] = 'Female'"]
-------------------

